<?xml version="1.0" encoding="utf-8"?>
<!-- =================================================================================== -->
<!-- |    This document was autogenerated by xacro from ur5_robot.urdf.xacro           | -->
<!-- |    EDITING THIS FILE BY HAND IS NOT RECOMMENDED                                 | -->
<!-- =================================================================================== -->
<robot name="combined">
  <!--robots pose-->
  <link name="world"/>

  <joint name="abb_6640_180_255_pose" type="fixed">
    <parent link="world"/>
    <child link="ABB_6640_180_255_base_link"/>
    <origin rpy="0.0 0.0 0.0" xyz="0 0 0.0"/><!--abb_6640_180_255 pedestal-->
  </joint>

  <joint name="abb_1200_5_90_pose" type="fixed">
    <parent link="world"/>
    <child link="abb_1200_5_90_pedestal"/>
    <origin rpy="0.0 0.0 0.0" xyz="0 5.0 5.0"/><!--abb_1200_5_90 pedestal-->
  </joint>

  <joint name="curve_1_pose" type="fixed">
    <parent link="world"/>
    <child link="curve_1_base_link"/>
    <origin rpy="0.0 0.0 0.0" xyz="0 2.0 0.0"/><!--abb_1200_5_90 pedestal-->
  </joint>
  <joint name="curve_2_pose" type="fixed">
    <parent link="world"/>
    <child link="curve_2_base_link"/>
    <origin rpy="0.0 0.0 0.0" xyz="0 -2.0 0.0"/><!--abb_1200_5_90 pedestal-->
  </joint>


  <!--curve_1 part-->
  <link name="curve_1_base_link">
    <!-- <collision>
      <origin rpy="0 0 0" xyz="-.124 0 .12"/>
      <geometry>
        <box size="1.016 .729 .24"/>
      </geometry>
    </collision> -->
    <visual name="visual">
      <geometry>
        <mesh filename="model://curve_1/meshes/wood.stl" scale="0.05 0.05 0.05"/>
      </geometry>
      <material name="orange">
        <color rgba=".04 .42 1 1"/>
      </material>
    </visual>
    <inertial>
      <origin rpy="0 0 0" xyz="0 0 .107 "/>
      <mass value="254.138"/>
      <inertia ixx="9.459" ixy="-.018" ixz="-.297" iyy="9.18" iyz=".003" izz="16.946"/>
    </inertial>
  </link>

  <!--curve_2 part-->
  <link name="curve_2_base_link">
    <!-- <collision>
      <origin rpy="0 0 0" xyz="-.124 0 .12"/>
      <geometry>
        <box size="1.016 .729 .24"/>
      </geometry>
    </collision> -->
    <visual name="visual">
      <geometry>
        <mesh filename="model://curve_2/meshes/generic_fan_blade.stl" scale="0.05 0.05 0.05"/>
      </geometry>
      <material name="orange">
        <color rgba=".04 .42 1 1"/>
      </material>
    </visual>
    <inertial>
      <origin rpy="0 0 0" xyz="0 0 .107 "/>
      <mass value="254.138"/>
      <inertia ixx="9.459" ixy="-.018" ixz="-.297" iyy="9.18" iyz=".003" izz="16.946"/>
    </inertial>
  </link>

  <!--abb_6640_180_255 part-->
  <link name="ABB_6640_180_255_base_link">
    <collision>
      <origin rpy="0 0 0" xyz="-.124 0 .12"/>
      <geometry>
        <box size="1.016 .729 .24"/>
      </geometry>
    </collision>
    <visual name="visual">
      <geometry>
        <mesh filename="model://abb_6640_180_255/meshes/visual/Base.stl"/>
      </geometry>
      <material name="orange">
        <color rgba="1 .42 .04 1"/>
      </material>
    </visual>
    <inertial>
      <origin rpy="0 0 0" xyz="0 0 .107 "/>
      <mass value="254.138"/>
      <inertia ixx="9.459" ixy="-.018" ixz="-.297" iyy="9.18" iyz=".003" izz="16.946"/>
    </inertial>
  </link>
  <link name="ABB_6640_180_255_link_1">
    <collision>
      <origin rpy="0 0 0" xyz="0 0 -.434"/>
      <geometry>
        <cylinder length=".224" radius=".309"/>
      </geometry>
    </collision>
    <collision>
      <origin rpy="1.571 0 0" xyz=".32 .302 0"/>
      <geometry>
        <cylinder length=".226" radius=".107"/>
      </geometry>
    </collision>
    <collision>
      <origin rpy="0 0 0" xyz="-.127 .127 -.215"/>
      <geometry>
        <cylinder length=".214" radius=".118"/>
      </geometry>
    </collision>
    <collision>
      <origin rpy="0 0 0" xyz="-.278 -.197 -.261"/>
      <geometry>
        <box size=".31 .528 .368"/>
      </geometry>
    </collision>
    <collision>
      <origin rpy="3.142 0 3.142" xyz="-.263 -.183 -.168"/>
      <geometry>
        <box size=".628 .387 .556"/>
      </geometry>
    </collision>
    <collision>
      <origin rpy="0 0 0" xyz=".238 .025 -.371"/>
      <geometry>
        <box size=".436 .328 .192"/>
      </geometry>
    </collision>
    <collision>
      <origin rpy="0 0 0" xyz=".32 .025 -.008"/>
      <geometry>
        <box size=".518 .328 .534"/>
      </geometry>
    </collision>
    <visual name="visual">
      <origin rpy="0 0 0" xyz="0 0 -.78"/>
      <geometry>
        <mesh filename="model://abb_6640_180_255/meshes/visual/Link1.stl"/>
      </geometry>
      <material name="orange"/>
    </visual>
    <visual name="visual2">
      <origin rpy="0 0 0" xyz="0 0 -.78"/>
      <geometry>
        <mesh filename="model://abb_6640_180_255/meshes/visual/LinkD1.stl"/>
      </geometry>
      <material name="orange"/>
    </visual>
    <inertial>
      <origin rpy="0 0 0" xyz="-.011 -.038 -.214 "/>
      <mass value="469.323"/>
      <inertia ixx="29.062" ixy="11.518" ixz="3.154" iyy="50.561" iyz="-.943" izz="46.087"/>
    </inertial>
  </link>
  <link name="ABB_6640_180_255_link_2">
    <collision>
      <origin rpy="1.571 0 0" xyz="-.015 -.295 .522"/>
      <geometry>
        <box size=".538 1.429 .311"/>
      </geometry>
    </collision>
    <collision>
      <origin rpy="1.571 0 0" xyz=".092 -.111 .22"/>
      <geometry>
        <box size=".251 .169 .058"/>
      </geometry>
    </collision>
    <visual name="visual">
      <origin rpy="0 0 0" xyz="-.32 0 -.78"/>
      <geometry>
        <mesh filename="model://abb_6640_180_255/meshes/visual/Link2.stl"/>
      </geometry>
      <material name="orange"/>
    </visual>
    <inertial>
      <origin rpy="0 0 0" xyz=".007 -.174 .441 "/>
      <mass value="153.009"/>
      <inertia ixx="37.57" ixy="-.08" ixz="-.145" iyy="37.47" iyz="-5.325" izz="3.526"/>
    </inertial>
  </link>
  <link name="ABB_6640_180_255_link_3">
    <collision>
      <origin rpy="0 1.571 0" xyz=".017 .249 .14"/>
      <geometry>
        <box size=".14 .14 .262"/>
      </geometry>
    </collision>
    <collision>
      <origin rpy="1.571 0 3.142" xyz="0 -.17 0"/>
      <geometry>
        <cylinder length=".135" radius=".238"/>
      </geometry>
    </collision>
    <collision>
      <origin rpy="1.571 0 0" xyz="0 .018 0"/>
      <geometry>
        <cylinder length=".242" radius=".118"/>
      </geometry>
    </collision>
    <collision>
      <origin rpy="0 1.571 0" xyz="-.2 .077 .19"/>
      <geometry>
        <box size=".405 .534 .171"/>
      </geometry>
    </collision>
    <collision>
      <origin rpy="0 1.571 0" xyz=".061 0 .2"/>
      <geometry>
        <cylinder length=".35" radius=".166"/>
      </geometry>
    </collision>
    <collision>
      <origin rpy="1.571 0 0" xyz="-.187 -.051 -.029"/>
      <geometry>
        <box size=".052 .085 .102"/>
      </geometry>
    </collision>
    <collision>
      <origin rpy="1.571 0 0" xyz=".178 -.051 .015"/>
      <geometry>
        <box size=".052 .109 .102"/>
      </geometry>
    </collision>
    <visual name="visual">
      <origin rpy="0 0 0" xyz="-.32 0 -1.855"/>
      <geometry>
        <mesh filename="model://abb_6640_180_255/meshes/visual/Link3.stl"/>
      </geometry>
      <material name="orange"/>
    </visual>
    <inertial>
      <origin rpy="0 0 0" xyz="-.045 .022 .139 "/>
      <mass value="212.29"/>
      <inertia ixx="6.575" ixy="-1.029" ixz="-.621" iyy="6.667" iyz=".976" izz="7.699"/>
    </inertial>
  </link>
  <link name="ABB_6640_180_255_link_4">
    <collision>
      <origin rpy="1.571 0 0" xyz="1.1425 -.139 0"/>
      <geometry>
        <cylinder length=".092" radius=".139"/>
      </geometry>
    </collision>
    <collision>
      <origin rpy="1.571 0 0" xyz="1.068 -.139 0"/>
      <geometry>
        <box size=".145 .278 .092"/>
      </geometry>
    </collision>
    <collision>
      <origin rpy="1.571 0 0" xyz="1.1425 .138 0"/>
      <geometry>
        <cylinder length=".075" radius=".139"/>
      </geometry>
    </collision>
    <collision>
      <origin rpy="0 1.571 0" xyz=".21 0 0"/>
      <geometry>
        <cylinder length=".98" radius=".122"/>
      </geometry>
    </collision>
    <collision>
      <origin rpy="1.571 0 0" xyz="1.068 .138 0"/>
      <geometry>
        <box size=".145 .278 .075"/>
      </geometry>
    </collision>
    <collision>
      <origin rpy="0 1.571 0" xyz=".83 -.005 0"/>
      <geometry>
        <box size=".278 .36 .331"/>
      </geometry>
    </collision>
    <visual name="visual">
      <origin rpy="0 0 0" xyz="-.32 0 -2.055"/>
      <geometry>
        <mesh filename="model://abb_6640_180_255/meshes/visual/Link4.stl"/>
      </geometry>
      <material name="orange"/>
    </visual>
    <inertial>
      <origin rpy="0 0 0" xyz=".606 -.008 0 "/>
      <mass value="185.22"/>
      <inertia ixx="1.744" ixy="-.722" ixz=".014" iyy="30.392" iyz="-.005" izz="31.078"/>
    </inertial>
  </link>
  <link name="ABB_6640_180_255_link_5">
    <collision>
      <origin rpy="-.697 -1.571 .697" xyz=".023 0 0"/>
      <geometry>
        <cylinder length=".307" radius=".107"/>
      </geometry>
    </collision>
    <visual name="visual">
      <origin rpy="0 0 0" xyz="-1.462 0 -2.055"/>
      <geometry>
        <mesh filename="model://abb_6640_180_255/meshes/visual/Link5.stl"/>
      </geometry>
      <material name="orange"/>
    </visual>
    <inertial>
      <origin rpy="0 0 0" xyz=".039 .001 0 "/>
      <mass value="26.117"/>
      <inertia ixx=".106" ixy="-.005" ixz="0" iyy=".207" iyz="0" izz=".218"/>
    </inertial>
  </link>
  <link name="ABB_6640_180_255_link_6">
    <collision>
      <origin rpy="0 1.571 0" xyz="-.019 0 0"/>
      <geometry>
        <cylinder length=".037" radius=".109"/>
      </geometry>
    </collision>
    <visual name="visual">
      <origin rpy="0 0 0" xyz="-1.662 0 -2.055"/>
      <geometry>
        <mesh filename="model://abb_6640_180_255/meshes/visual/Link6.stl"/>
      </geometry>
      <material name="orange"/>
    </visual>
    <inertial>
      <origin rpy="0 0 0" xyz="-.019 -.001 0 "/>
      <mass value="3.371"/>
      <inertia ixx=".017" ixy="0" ixz="0" iyy=".009" iyz="0" izz=".009"/>
    </inertial>
  </link>
  <link name="ABB_6640_180_255_tool">
    <visual name="visual">
      <origin rpy="0 0 0" xyz="0 0 0"/>
      <geometry>
        <mesh filename="model://paintgun/meshes/paint_gun.stl" scale="0.04 0.04 0.04"/>
      </geometry>
      <material name="orange"/>
    </visual>

  </link>
  <!-- end of link list -->
  <!-- joint list -->
  <joint name="ABB_6640_180_255_joint_1" type="revolute">
    <origin rpy="0 0 0" xyz="0 0 0.780"/>
    <axis xyz="0 0 1"/>
    <parent link="ABB_6640_180_255_base_link"/>
    <child link="ABB_6640_180_255_link_1"/>
    <limit effort="0" lower="-2.967" upper="2.967" velocity="1.7453"/>
  </joint>
  <joint name="ABB_6640_180_255_joint_2" type="revolute">
    <origin rpy="0 0 0" xyz="0.320 0 0"/>
    <axis xyz="0 1 0"/>
    <parent link="ABB_6640_180_255_link_1"/>
    <child link="ABB_6640_180_255_link_2"/>
    <limit effort="0" lower="-1.134" upper="1.4855" velocity="1.5707"/>
  </joint>
  <joint name="ABB_6640_180_255_joint_3" type="revolute">
    <origin rpy="0 0 0" xyz="0 0 1.075"/>
    <axis xyz="0 1 0"/>
    <parent link="ABB_6640_180_255_link_2"/>
    <child link="ABB_6640_180_255_link_3"/>
    <limit effort="0" lower="-3.142" upper="1.222" velocity="1.5707"/>
  </joint>
  <joint name="ABB_6640_180_255_joint_4" type="revolute">
    <origin rpy="0 0 0" xyz="0 0 0.2"/>
    <axis xyz="1 0 0"/>
    <parent link="ABB_6640_180_255_link_3"/>
    <child link="ABB_6640_180_255_link_4"/>
    <limit effort="0" lower="-5.236" upper="5.236" velocity="2.9671"/>
  </joint>
  <joint name="ABB_6640_180_255_joint_5" type="revolute">
    <origin rpy="0 0 0" xyz="1.1425 0 0 "/>
    <axis xyz="0 1 0"/>
    <parent link="ABB_6640_180_255_link_4"/>
    <child link="ABB_6640_180_255_link_5"/>
    <limit effort="0" lower="-2.094" upper="2.094" velocity="2.4435"/>
  </joint>
  <joint name="ABB_6640_180_255_joint_6" type="revolute">
    <origin rpy="0 0 0" xyz="0.2 0 0 "/>
    <axis xyz="1 0 0"/>
    <parent link="ABB_6640_180_255_link_5"/>
    <child link="ABB_6640_180_255_link_6"/>
    <limit effort="0" lower="-6.283" upper="6.283" velocity="3.3161"/>
  </joint>
  <joint name="joint_6-tool0" type="fixed">
    <parent link="ABB_6640_180_255_link_6"/>
    <child link="ABB_6640_180_255_tool"/>
    <origin rpy="0 1.57079632679 0" xyz="0 0 0"/>
  </joint>
  <!-- end of joint list -->


  <!--abb_1200_5_90 part-->
  <joint name="ABB_1200_5_90_joint_1" type="revolute">
    <parent link="ABB_1200_5_90_base_link"/>
    <child link="ABB_1200_5_90_link_1"/>
    <origin rpy="0 0 0" xyz="0     0     0.3991"/>
    <axis xyz="0 0 1"/>
    <limit effort="1000.0" lower="-2.967" upper="2.967" velocity="5.027"/>
  </joint>
  <joint name="ABB_1200_5_90_joint_2" type="revolute">
    <parent link="ABB_1200_5_90_link_1"/>
    <child link="ABB_1200_5_90_link_2"/>
    <origin rpy="0 0 0" xyz="0 0 0"/>
    <axis xyz="0 1 0"/>
    <limit effort="1000.0" lower="-1.745" upper="2.269" velocity="4.189"/>
  </joint>
  <joint name="ABB_1200_5_90_joint_3" type="revolute">
    <parent link="ABB_1200_5_90_link_2"/>
    <child link="ABB_1200_5_90_link_3"/>
    <origin rpy="0 0 0" xyz="0    0    0.448"/>
    <axis xyz="0 1 0"/>
    <limit effort="1000.0" lower="-3.491" upper="1.222" velocity="5.236"/>
  </joint>
  <joint name="ABB_1200_5_90_joint_4" type="revolute">
    <parent link="ABB_1200_5_90_link_3"/>
    <child link="ABB_1200_5_90_link_4"/>
    <origin rpy="0 0 0" xyz="0    0    0.042"/>
    <axis xyz="1 0 0"/>
    <limit effort="1000.0" lower="-4.712" upper="4.712" velocity="6.981"/>
  </joint>
  <joint name="ABB_1200_5_90_joint_5" type="revolute">
    <parent link="ABB_1200_5_90_link_4"/>
    <child link="ABB_1200_5_90_link_5"/>
    <origin rpy="0 0 0" xyz="0.451 0    0"/>
    <axis xyz="0 1 0"/>
    <limit effort="1000.0" lower="-2.269" upper="2.269" velocity="7.069"/>
  </joint>
  <joint name="ABB_1200_5_90_joint_6" type="revolute">
    <parent link="ABB_1200_5_90_link_5"/>
    <child link="ABB_1200_5_90_link_6"/>
    <origin rpy="0 0 0" xyz="0.082 0    0"/>
    <axis xyz="1 0 0"/>
    <limit effort="1000.0" lower="-6.283" upper="6.283" velocity="10.472"/>
  </joint>
  <joint name="abb_1200_5_90_pedestal_JOINT_0" type="fixed">
    <parent link="abb_1200_5_90_pedestal"/>
    <child link="ABB_1200_5_90_base_link"/>
    <origin rpy="0 0 0" xyz="0 0 0"/>
    <axis xyz="0 0 0"/>
    <limit effort="0" lower="0" upper="0" velocity="0"/>
  </joint>
  <link name="ABB_1200_5_90_base_link">
    <inertial>
      <mass value="13.7742"/>
      <origin rpy="0 0 0" xyz="-0.02898  0.00059  0.11273"/>
      <inertia ixx="0.101998" ixy="0.000495482" ixz="0.000311158" iyy="0.13969" iyz="-0.000245375" izz="0.130433"/>
    </inertial>
    <visual name="ABB_1200_5_90_base_link_fixed_joint_lump__visual_visual">
      <origin rpy="0 0 0" xyz="0 0 0"/>
      <geometry>
        <mesh filename="model://abb_1200_5_90/meshes/visual/base_link.dae" scale="1 1 1"/>
      </geometry>
    </visual>
  </link>
  <link name="abb_1200_5_90_pedestal">
    <inertial>
      <mass value="1"/>
      <origin rpy="0 0 0" xyz="0 0 0"/>
      <inertia ixx="0.145833" ixy="0" ixz="0" iyy="0.145833" iyz="0" izz="0.125"/>
    </inertial>
    <visual name="ABB_1200_5_90_visual">
      <origin rpy="0 0 0" xyz="0   0  -0.5"/>
      <geometry>
        <cylinder length="1.0" radius="0.2"/>
      </geometry>
    </visual>
  </link>
  <link name="ABB_1200_5_90_link_1">
    <inertial>
      <mass value="11.8419"/>
      <origin rpy="0 0 0" xyz="0.00087 -0.00063 -0.06288"/>
      <inertia ixx="0.11194" ixy="-4.54988e-05" ixz="0.000280961" iyy="0.0915159" iyz="-0.000109905" izz="0.0876456"/>
    </inertial>
    <collision name="ABB_1200_5_90_link_1_fixed_joint_lump__collision_collision">
      <origin rpy="0 0 0" xyz="0 0 0"/>
      <geometry>
        <mesh filename="model://abb_1200_5_90/meshes/collision/link_1.stl" scale="1 1 1"/>
      </geometry>
    </collision>
    <visual name="ABB_1200_5_90_link_1_fixed_joint_lump__visual_visual">
      <origin rpy="0 0 0" xyz="0 0 0"/>
      <geometry>
        <mesh filename="model://abb_1200_5_90/meshes/visual/link_1.dae" scale="1 1 1"/>
      </geometry>
    </visual>
  </link>
  <link name="ABB_1200_5_90_link_2">
    <inertial>
      <mass value="17.5394"/>
      <origin rpy="0 0 0" xyz="-0.00092 -0.00049  0.25005"/>
      <inertia ixx="0.493558" ixy="1.32136e-05" ixz="0.000209024" iyy="0.462939" iyz="-0.00179901" izz="0.0894214"/>
    </inertial>
    <collision name="ABB_1200_5_90_link_2_fixed_joint_lump__collision_collision">
      <origin rpy="0 0 0" xyz="0 0 0"/>
      <geometry>
        <mesh filename="model://abb_1200_5_90/meshes/collision/link_2.stl" scale="1 1 1"/>
      </geometry>
    </collision>
    <visual name="ABB_1200_5_90_link_2_fixed_joint_lump__visual_visual">
      <origin rpy="0 0 0" xyz="0 0 0"/>
      <geometry>
        <mesh filename="model://abb_1200_5_90/meshes/visual/link_2.dae" scale="1 1 1"/>
      </geometry>
    </visual>
  </link>
  <link name="ABB_1200_5_90_link_3">
    <inertial>
      <mass value="7.46365"/>
      <origin rpy="0 0 0" xyz="0.09958 0.00114 0.03233"/>
      <inertia ixx="0.0252424" ixy="0.000142737" ixz="-0.00565542" iyy="0.0906438" iyz="0.000142213" izz="0.0825079"/>
    </inertial>
    <collision name="ABB_1200_5_90_link_3_fixed_joint_lump__collision_collision">
      <origin rpy="0 0 0" xyz="0 0 0"/>
      <geometry>
        <mesh filename="model://abb_1200_5_90/meshes/collision/link_3.stl" scale="1 1 1"/>
      </geometry>
    </collision>
    <visual name="ABB_1200_5_90_link_3_fixed_joint_lump__visual_visual">
      <origin rpy="0 0 0" xyz="0 0 0"/>
      <geometry>
        <mesh filename="model://abb_1200_5_90/meshes/visual/link_3.dae" scale="1 1 1"/>
      </geometry>
    </visual>
  </link>
  <link name="ABB_1200_5_90_link_4">
    <inertial>
      <mass value="2.74436"/>
      <origin rpy="0 0 0" xyz="0.38167 0.00126 0.00516"/>
      <inertia ixx="0.00573099" ixy="-0.000131119" ixz="0.000380232" iyy="0.0118352" iyz="-2.26565e-05" izz="0.0114428"/>
    </inertial>
    <collision name="ABB_1200_5_90_link_4_fixed_joint_lump__collision_collision">
      <origin rpy="0 0 0" xyz="0 0 0"/>
      <geometry>
        <mesh filename="model://abb_1200_5_90/meshes/collision/link_4.stl" scale="1 1 1"/>
      </geometry>
    </collision>
    <visual name="ABB_1200_5_90_link_4_fixed_joint_lump__visual_visual">
      <origin rpy="0 0 0" xyz="0 0 0"/>
      <geometry>
        <mesh filename="model://abb_1200_5_90/meshes/visual/link_4.dae" scale="1 1 1"/>
      </geometry>
    </visual>
  </link>
  <link name="ABB_1200_5_90_link_5">
    <inertial>
      <mass value="0.62953"/>
      <origin rpy="0 0 0" xyz="0.01119 -0.00105  0.0001"/>
      <inertia ixx="0.000502815" ixy="-1.03173e-05" ixz="-8.74347e-08" iyy="0.00108856" iyz="2.07657e-07" izz="0.000918873"/>
    </inertial>
    <collision name="ABB_1200_5_90_link_5_fixed_joint_lump__collision_collision">
      <origin rpy="0 0 0" xyz="0 0 0"/>
      <geometry>
        <mesh filename="model://abb_1200_5_90/meshes/collision/link_5.stl" scale="1 1 1"/>
      </geometry>
    </collision>
    <visual name="ABB_1200_5_90_link_5_fixed_joint_lump__visual_visual">
      <origin rpy="0 0 0" xyz="0 0 0"/>
      <geometry>
        <mesh filename="model://abb_1200_5_90/meshes/visual/link_5.dae" scale="1 1 1"/>
      </geometry>
    </visual>
  </link>
  <link name="ABB_1200_5_90_link_6">
    <inertial>
      <mass value="0.137"/>
      <origin rpy="0 0 0" xyz="-0.00706 -0.00017  0"/>
      <inertia ixx="0.001" ixy="0" ixz="0" iyy="0.001" iyz="0" izz="0.001"/>
    </inertial>
    <collision name="ABB_1200_5_90_link_6_fixed_joint_lump__collision_collision">
      <origin rpy="0 0 0" xyz="0 0 0"/>
      <geometry>
        <mesh filename="model://abb_1200_5_90/meshes/collision/link_6.stl" scale="1 1 1"/>
      </geometry>
    </collision>
    <visual name="ABB_1200_5_90_link_6_fixed_joint_lump__visual_visual">
      <origin rpy="0 0 0" xyz="0 0 0"/>
      <geometry>
        <mesh filename="model://abb_1200_5_90/meshes/visual/link_6.dae" scale="1 1 1"/>
      </geometry>
    </visual>
  </link>


</robot>
