<?xml version="1.0" encoding="utf-8"?>
<!-- =================================================================================== -->
<!-- |    This document was autogenerated by xacro from ur5_robot.urdf.xacro           | -->
<!-- |    EDITING THIS FILE BY HAND IS NOT RECOMMENDED                                 | -->
<!-- =================================================================================== -->
<robot name="fanuc_cell">
  <!--robots pose-->
  <link name="world"/>
  
  <joint name="FANUC_m10ia_pose" type="fixed">
    <parent link="world"/>
    <child link="FANUC_m10ia_base_link"/>
    <origin rpy="0.0 0.0 0.0" xyz="0 0.0 5.0"/><!--ABB_1200_5_90 pedestal-->
  </joint>
  
  <joint name="FANUC_lrmate200id_pose" type="fixed">
    <parent link="world"/>
    <child link="FANUC_lrmate200id_base_link"/>
    <origin rpy="0.0 0.0 0.0" xyz="0 -5.0 5.0"/><!--ABB_1200_5_90 pedestal-->
  </joint>

  <joint name="curve_1_pose" type="fixed">
    <parent link="world"/>
    <child link="curve_1_base_link"/>
    <origin rpy="0.0 0.0 0.0" xyz="0 2.0 0.0"/><!--ABB_1200_5_90 pedestal-->
  </joint>
  <joint name="curve_2_pose" type="fixed">
    <parent link="world"/>
    <child link="curve_2_base_link"/>
    <origin rpy="0.0 0.0 0.0" xyz="0 -2.0 0.0"/><!--ABB_1200_5_90 pedestal-->
  </joint>


  <!--curve_1 part-->
  <link name="curve_1_base_link">
    <collision>
      <geometry>
        <mesh filename="model://curve_1/meshes/wood.stl" scale="0.001 0.001 0.001"/>
      </geometry>
    </collision>
    <visual name="visual">
      <geometry>
        <mesh filename="model://curve_1/meshes/wood.stl" scale="0.001 0.001 0.001"/>
      </geometry>
      <material name="orange">
        <color rgba=".04 .42 1 1"/>
      </material>
    </visual>
    <inertial>
      <origin rpy="0 0 0" xyz="0 0 .107 "/>
      <mass value="254.138"/>
      <inertia ixx="9.459" ixy="-.018" ixz="-.297" iyy="9.18" iyz=".003" izz="16.946"/>
    </inertial>
  </link>

  <!--curve_2 part-->
  <link name="curve_2_base_link">
    <collision>
      <geometry>
        <mesh filename="model://curve_2/meshes/generic_fan_blade.stl" scale="0.001 0.001 0.001"/>
      </geometry>
    </collision>
    <visual name="visual">
      <geometry>
        <mesh filename="model://curve_2/meshes/generic_fan_blade.stl" scale="0.001 0.001 0.001"/>
      </geometry>
      <material name="orange">
        <color rgba=".04 .42 1 1"/>
      </material>
    </visual>
    <inertial>
      <origin rpy="0 0 0" xyz="0 0 .107 "/>
      <mass value="254.138"/>
      <inertia ixx="9.459" ixy="-.018" ixz="-.297" iyy="9.18" iyz=".003" izz="16.946"/>
    </inertial>
  </link>

  <link name="Wall1">
    <visual>
      <geometry>
        <box size="0.01 1.7 1.3"/>
      </geometry>
      <material name="">
        <color rgba="0.1490196078431373 0.14901960784313725 0.72941176470588237 0.1"/>
      </material>
    </visual>
    <collision>
      <geometry>
        <box size="0.01 1.7 1.3"/>
      </geometry>
    </collision>
  </link>
  <joint name="Wall1_pose" type="fixed">
    <parent link="world"/>
    <child link="Wall1"/>
    <origin rpy="0.0 0.0 0" xyz="-0.405 -0.27 0.8"/>
  </joint>

  <link name="Wall2">
    <visual>
      <geometry>
        <box size="1.8 0.01 1.3"/>
      </geometry>
      <material name="">
        <color rgba="0.1490196078431373 0.14901960784313725 0.72941176470588237 0.1"/>
      </material>
    </visual>
    <collision>
      <geometry>
        <box size="1.8 0.01 1.3"/>
      </geometry>
    </collision>
  </link>
  <joint name="Wall2_pose" type="fixed">
    <parent link="world"/>
    <child link="Wall2"/>
    <origin rpy="0.0 0.0 0" xyz="0.5 -1.115 0.8"/>
  </joint>

  <link name="Wall3">
    <visual>
      <geometry>
        <box size="0.01 1.7 1.3"/>
      </geometry>
      <material name="">
        <color rgba="0.1490196078431373 0.14901960784313725 0.72941176470588237 0.1"/>
      </material>
    </visual>
    <collision>
      <geometry>
        <box size="0.01 1.7 1.3"/>
      </geometry>
    </collision>
  </link>
  <joint name="Wall3_pose" type="fixed">
    <parent link="world"/>
    <child link="Wall3"/>
    <origin rpy="0.0 0.0 0" xyz="1.405 -0.27 0.8"/>
  </joint>

  <!-- <link name="Wall4">
    <visual>
      <geometry>
        <box size="1.8 0.01 1.3"/>
      </geometry>
      <material name="">
        <color rgba="0.1490196078431373 0.14901960784313725 0.72941176470588237 0.1"/>
      </material>
    </visual>
    <collision>
      <geometry>
        <box size="1.8 0.01 1.3"/>
      </geometry>
    </collision>
  </link>
  <joint name="Wall4_pose" type="fixed">
    <parent link="world"/>
    <child link="Wall4"/>
    <origin rpy="0.0 0.0 0" xyz="0.5 0.585 0.8"/>
  </joint> -->

  <link name="Ground">
    <visual>
      <geometry>
        <box size="1.8 1.7 0.01"/>
      </geometry>
      <material name="">
        <color rgba="0.1490196078431373 0.14901960784313725 0.72941176470588237 0.1"/>
      </material>
    </visual>
    <collision>
      <geometry>
        <box size="1.8 1.7 0.01"/>
      </geometry>
    </collision>
  </link>
  <joint name="Ground_pose" type="fixed">
    <parent link="world"/>
    <child link="Ground"/>
    <origin rpy="0.0 0.0 0" xyz="0.5 -0.27 0.15"/>
  </joint>

  <link name="Ceiling">
    <visual>
      <geometry>
        <box size="1.8 1.7 0.01"/>
      </geometry>
      <material name="">
        <color rgba="0.1490196078431373 0.14901960784313725 0.72941176470588237 0.1"/>
      </material>
    </visual>
    <collision>
      <geometry>
        <box size="1.8 1.7 0.01"/>
      </geometry>
    </collision>
  </link>
  <joint name="Ceiling_pose" type="fixed">
    <parent link="world"/>
    <child link="Ceiling"/>
    <origin rpy="0.0 0.0 0" xyz="0.5 -0.27 1.45"/>
  </joint>

  <!-- FANUC m10ia part -->
  <link name="FANUC_m10ia_base_link">
    <visual>
      <origin rpy="0 0 0" xyz="0 0 0"/>
      <geometry>
        <mesh filename="model://FANUC_m10ia/meshes/m10ia/visual/base_link.stl"/>
      </geometry>
      <material name="">
        <color rgba="0.4 0.4 0.4 1.0"/>
      </material>
    </visual>
    <collision>
      <origin rpy="0 0 0" xyz="0 0 0"/>
      <geometry>
        <mesh filename="model://FANUC_m10ia/meshes/m10ia/collision/base_link.stl"/>
      </geometry>
    </collision>
  </link>
  <link name="FANUC_m10ia_link_1">
    <visual>
      <origin rpy="0 0 0" xyz="0.095 -0.035 0.01"/>
      <geometry>
        <!-- <mesh filename="model://FANUC_m10ia/meshes/m10ia/visual/link_1.stl"/> -->
        <sphere radius="0.24"/>
      </geometry>
      <material name="">
        <color rgba="0.96 0.76 0.13 1.0"/>
      </material>
    </visual>
    <collision>
      <origin rpy="0 0 0" xyz="0.095 -0.035 0.01"/>
      <geometry>
        <!-- <mesh filename="model://FANUC_m10ia/meshes/m10ia/visual/link_1.stl"/> -->
        <sphere radius="0.24"/>
      </geometry>
    </collision>
  </link>
  <link name="FANUC_m10ia_link_2">
    <visual>
      <origin rpy="0 0 0" xyz="0 -0.14 0.28"/>
      <geometry>
        <!-- <mesh filename="model://FANUC_m10ia/meshes/m10ia/visual/link_2.stl"/> -->
        <cylinder radius="0.09" length="0.58"/>
      </geometry>
      <material name="">
        <color rgba="0.96 0.76 0.13 1.0"/>
      </material>
    </visual>
    <collision>
      <origin rpy="0 0 0" xyz="0 -0.14 0.28"/>
      <geometry>
        <!-- <mesh filename="model://FANUC_m10ia/meshes/m10ia/collision/link_2.stl"/> -->
        <cylinder radius="0.09" length="0.58"/>
      </geometry>
    </collision>
  </link>
  <link name="FANUC_m10ia_link_3">
    <visual>
      <origin rpy="0 0 0" xyz="0.065 0.02 0.09"/>
      <geometry>
        <!-- <mesh filename="model://FANUC_m10ia/meshes/m10ia/visual/link_3.stl"/> -->
        <sphere radius="0.205"/>
      </geometry>
      <material name="">
        <color rgba="0.96 0.76 0.13 1.0"/>
      </material>
    </visual>
    <collision>
      <origin rpy="0 0 0" xyz="0 0 0"/>
      <geometry>
        <!-- <mesh filename="model://FANUC_m10ia/meshes/m10ia/collision/link_3.stl"/> -->
        <sphere radius="0.205"/>
      </geometry>
    </collision>
  </link>
  <link name="FANUC_m10ia_link_4">
    <visual>
      <origin rpy="0 1.57079632679 0" xyz="0.415 -0.03 0"/>
      <geometry>
        <!-- <mesh filename="model://FANUC_m10ia/meshes/m10ia/visual/link_4.stl"/> -->
        <cylinder radius="0.085" length="0.41"/>
      </geometry>
      <material name="">
        <color rgba="0.96 0.76 0.13 0.0"/> <!-- color not changing??? -->
      </material>
    </visual>
    <collision>
      <origin rpy="0 1.57079632679 0" xyz="0.415 -0.03 0"/>
      <geometry>
        <!-- <mesh filename="model://FANUC_m10ia/meshes/m10ia/collision/link_4.stl"/> -->
        <cylinder radius="0.085" length="0.41"/>
      </geometry>
    </collision>
  </link>
  <link name="FANUC_m10ia_link_5">
    <visual>
      <origin rpy="0 1.57079632679 0" xyz="0.0325 0 0"/>
      <geometry>
        <!-- <mesh filename="model://FANUC_m10ia/meshes/m10ia/visual/link_5.stl"/> -->
        <cylinder radius="0.06" length="0.09"/>
      </geometry>
      <material name="">
        <color rgba="0.96 0.76 0.13 1.0"/>
      </material>
    </visual>
    <collision>
      <origin rpy="0 1.57079632679 0" xyz="0.0325 0 0"/>
      <geometry>
        <!-- <mesh filename="model://FANUC_m10ia/meshes/m10ia/collision/link_5.stl"/> -->
        <cylinder radius="0.06" length="0.09"/>
      </geometry>
    </collision>
  </link>
  <link name="FANUC_m10ia_link_6">
    <visual>
      <origin rpy="0 0 0" xyz="0 0 0"/>
      <geometry>
        <mesh filename="model://FANUC_m10ia/meshes/m10ia/visual/link_6.stl"/>
      </geometry>
      <material name="">
        <color rgba="0.15 0.15 0.15 1.0"/>
      </material>
    </visual>
    <collision>
      <origin rpy="0 0 0" xyz="0 0 0"/>
      <geometry>
        <mesh filename="model://FANUC_m10ia/meshes/m10ia/collision/link_6.stl"/>
      </geometry>
    </collision>
  </link>
  <!-- <link name="FANUC_m10ia_tool">
    <visual name="visual">
      <origin rpy="0 0 0" xyz="0 0 0"/>
      <geometry>
        <mesh filename="model://paintgun/meshes/paint_gun.stl" scale="0.001 0.001 0.001"/>
      </geometry>
      <material name="">
        <color rgba="0.96 0.76 0.13 1.0"/>
      </material>
    </visual>
    <collision>
      <origin rpy="0 0 0" xyz="0 0 0"/>
      <geometry>
        <mesh filename="model://paintgun/meshes/paint_gun.stl" scale="0.001 0.001 0.001"/>
      </geometry>
    </collision>
  </link> -->
  <link name="FANUC_m10ia_dcstool">
    <visual name="visual">
      <origin rpy="0 0 0" xyz="0 0 0.075"/>
      <geometry>
        <!-- <mesh filename="model://paintgun/meshes/paint_gun.stl" scale="0.001 0.001 0.001"/> -->
        <box size="0.3 0.3 0.15"/>
      </geometry>
      <material name="">
        <color rgba="0.96 0.76 0.13 1.0"/>
      </material>
    </visual>
    <collision>
      <origin rpy="0 0 0" xyz="0 0 0.075"/>
      <geometry>
        <!-- <mesh filename="model://paintgun/meshes/paint_gun.stl" scale="0.001 0.001 0.001"/> -->
        <box size="0.3 0.3 0.15"/>
      </geometry>
    </collision>
  </link>

  <!-- joints: main serial chain -->
  <joint name="FANUC_m10ia_joint_1" type="revolute">
    <origin rpy="0 0 0" xyz="0 0 0.450"/>
    <parent link="FANUC_m10ia_base_link"/>
    <child link="FANUC_m10ia_link_1"/>
    <axis xyz="0 0 1"/>
    <limit effort="0" lower="-3.14" upper="3.14" velocity="3.67"/>
  </joint>
  <joint name="FANUC_m10ia_joint_2" type="revolute">
    <origin rpy="0 0 0" xyz="0.150 0 0"/>
    <parent link="FANUC_m10ia_link_1"/>
    <child link="FANUC_m10ia_link_2"/>
    <axis xyz="0 1 0"/>
    <limit effort="0" lower="-1.57" upper="2.79" velocity="3.32"/>
  </joint>
  <joint name="FANUC_m10ia_joint_3" type="revolute">
    <origin rpy="0 0 0" xyz="0 0 0.600"/>
    <parent link="FANUC_m10ia_link_2"/>
    <child link="FANUC_m10ia_link_3"/>
    <axis xyz="0 -1 0"/>
    <limit effort="0" lower="-3.14" upper="4.61" velocity="3.67"/>
  </joint>
  <joint name="FANUC_m10ia_joint_4" type="revolute">
    <origin rpy="0 0 0" xyz="0 0 0.200"/>
    <parent link="FANUC_m10ia_link_3"/>
    <child link="FANUC_m10ia_link_4"/>
    <axis xyz="-1 0 0"/>
    <limit effort="0" lower="-3.31" upper="3.31" velocity="6.98"/>
  </joint>
  <joint name="FANUC_m10ia_joint_5" type="revolute">
    <origin rpy="0 0 0" xyz="0.640 0 0"/>
    <parent link="FANUC_m10ia_link_4"/>
    <child link="FANUC_m10ia_link_5"/>
    <axis xyz="0 -1 0"/>
    <limit effort="0" lower="-3.31" upper="3.31" velocity="6.98"/>
  </joint>
  <joint name="FANUC_m10ia_joint_6" type="revolute">
    <origin rpy="0 0 0" xyz="0.100 0 0"/>
    <parent link="FANUC_m10ia_link_5"/>
    <child link="FANUC_m10ia_link_6"/>
    <axis xyz="-1 0 0"/>
    <limit effort="0" lower="-6.28" upper="6.28" velocity="10.47"/>
  </joint>
  <!-- <joint name="FANUC_m10ia_joint_6-tool0" type="fixed">
    <parent link="FANUC_m10ia_link_6"/>
    <child link="FANUC_m10ia_tool"/>
    <origin rpy="0 1.57079632679 0" xyz="0 0 0"/>
  </joint> -->
  <joint name="FANUC_m10ia_joint_6_dcs" type="fixed">
    <parent link="FANUC_m10ia_link_6"/>
    <child link="FANUC_m10ia_dcstool"/>
    <origin rpy="0 1.57079632679 0" xyz="0 0 0"/>
  </joint>

  <!-- FANUC lrmate200id part -->
  <link name="FANUC_lrmate200id_base_link">
    <visual>
      <origin rpy="0 0 0" xyz="0 0 0"/>
      <geometry>
        <mesh filename="model://FANUC_lrmate200id/meshes/lrmate200id/visual/base_link.stl"/>
      </geometry>
      <material name="">
        <color rgba="0.2784313725490196 0.2784313725490196 0.2784313725490196 1.0"/>
      </material>
    </visual>
    <collision>
      <origin rpy="0 0 0" xyz="0 0 0"/>
      <geometry>
        <mesh filename="model://FANUC_lrmate200id/meshes/lrmate200id/collision/base_link.stl"/>
      </geometry>
    </collision>
  </link>
  <link name="FANUC_lrmate200id_link_1">
    <visual>
      <origin rpy="0 0 0" xyz="0 0 0"/>
      <geometry>
        <mesh filename="model://FANUC_lrmate200id/meshes/lrmate200id/visual/link_1.stl"/>
      </geometry>
      <material name="">
        <color rgba="0.96 0.76 0.13 1.0"/>
      </material>
    </visual>
    <collision>
      <origin rpy="0 0 0" xyz="0 0 0"/>
      <geometry>
        <mesh filename="model://FANUC_lrmate200id/meshes/lrmate200id/collision/link_1.stl"/>
      </geometry>
    </collision>
  </link>
  <link name="FANUC_lrmate200id_link_2">
    <visual>
      <origin rpy="0 0 0" xyz="0 0 0"/>
      <geometry>
        <mesh filename="model://FANUC_lrmate200id/meshes/lrmate200id/visual/link_2.stl"/>
      </geometry>
      <material name="">
        <color rgba="0.96 0.76 0.13 1.0"/>
      </material>
    </visual>
    <collision>
      <origin rpy="0 0 0" xyz="0 0 0"/>
      <geometry>
        <mesh filename="model://FANUC_lrmate200id/meshes/lrmate200id/collision/link_2.stl"/>
      </geometry>
    </collision>
  </link>
  <link name="FANUC_lrmate200id_link_3">
    <visual>
      <origin rpy="0 0 0" xyz="0 0 0"/>
      <geometry>
        <mesh filename="model://FANUC_lrmate200id/meshes/lrmate200id/visual/link_3.stl"/>
      </geometry>
      <material name="">
        <color rgba="0.96 0.76 0.13 1.0"/>
      </material>
    </visual>
    <collision>
      <origin rpy="0 0 0" xyz="0 0 0"/>
      <geometry>
        <mesh filename="model://FANUC_lrmate200id/meshes/lrmate200id/collision/link_3.stl"/>
      </geometry>
    </collision>
  </link>
  <link name="FANUC_lrmate200id_link_4">
    <visual>
      <origin rpy="0 0 0" xyz="0 0 0"/>
      <geometry>
        <mesh filename="model://FANUC_lrmate200id/meshes/lrmate200id/visual/link_4.stl"/>
      </geometry>
      <material name="">
        <color rgba="0.96 0.76 0.13 1.0"/>
      </material>
    </visual>
    <collision>
      <origin rpy="0 0 0" xyz="0 0 0"/>
      <geometry>
        <mesh filename="model://FANUC_lrmate200id/meshes/lrmate200id/collision/link_4.stl"/>
      </geometry>
    </collision>
  </link>
  <link name="FANUC_lrmate200id_link_5">
    <visual>
      <origin rpy="0 0 0" xyz="0 0 0"/>
      <geometry>
        <mesh filename="model://FANUC_lrmate200id/meshes/lrmate200id/visual/link_5.stl"/>
      </geometry>
      <material name="">
        <color rgba="0.96 0.76 0.13 1.0"/>
      </material>
    </visual>
    <collision>
      <origin rpy="0 0 0" xyz="0 0 0"/>
      <geometry>
        <mesh filename="model://FANUC_lrmate200id/meshes/lrmate200id/collision/link_5.stl"/>
      </geometry>
    </collision>
  </link>
  <link name="FANUC_lrmate200id_link_6">
    <visual>
      <origin rpy="0 0 0" xyz="0 0 0"/>
      <geometry>
        <mesh filename="model://FANUC_lrmate200id/meshes/lrmate200id/visual/link_6.stl"/>
      </geometry>
      <material name="">
        <color rgba="0.15 0.15 0.15 1.0"/>
      </material>
    </visual>
    <collision>
      <origin rpy="0 0 0" xyz="0 0 0"/>
      <geometry>
        <mesh filename="model://FANUC_lrmate200id/meshes/lrmate200id/collision/link_6.stl"/>
      </geometry>
    </collision>
  </link>
  <!-- joints: main serial chain -->
  <joint name="FANUC_lrmate200id_joint_1" type="revolute">
    <origin rpy="0 0 0" xyz="0 0 0.330"/>
    <parent link="FANUC_lrmate200id_base_link"/>
    <child link="FANUC_lrmate200id_link_1"/>
    <axis xyz="0 0 1"/>
    <limit effort="0" lower="-2.9670597283903604" upper="2.9670597283903604" velocity="7.853981633974483"/>
  </joint>
  <joint name="FANUC_lrmate200id_joint_2" type="revolute">
    <origin rpy="0 0 0" xyz="0.050 0 0"/>
    <parent link="FANUC_lrmate200id_link_1"/>
    <child link="FANUC_lrmate200id_link_2"/>
    <axis xyz="0 1 0"/>
    <limit effort="0" lower="-1.7453292519943295" upper="2.530727415391778" velocity="6.632251157578453"/>
  </joint>
  <joint name="FANUC_lrmate200id_joint_3" type="revolute">
    <origin rpy="0 0 0" xyz="0 0 0.330"/>
    <parent link="FANUC_lrmate200id_link_2"/>
    <child link="FANUC_lrmate200id_link_3"/>
    <axis xyz="0 -1 0"/>
    <limit effort="0" lower="-1.2217304763960306" upper="3.5779249665883754" velocity="9.075712110370514"/>
  </joint>
  <joint name="FANUC_lrmate200id_joint_4" type="revolute">
    <origin rpy="0 0 0" xyz="0 0 0.035"/>
    <parent link="FANUC_lrmate200id_link_3"/>
    <child link="FANUC_lrmate200id_link_4"/>
    <axis xyz="-1 0 0"/>
    <limit effort="0" lower="-3.3161255787892263" upper="3.3161255787892263" velocity="9.599310885968812"/>
  </joint>
  <joint name="FANUC_lrmate200id_joint_5" type="revolute">
    <origin rpy="0 0 0" xyz="0.335 0 0"/>
    <parent link="FANUC_lrmate200id_link_4"/>
    <child link="FANUC_lrmate200id_link_5"/>
    <axis xyz="0 -1 0"/>
    <limit effort="0" lower="-2.181661564992912" upper="2.181661564992912" velocity="9.512044423369096"/>
  </joint>
  <joint name="FANUC_lrmate200id_joint_6" type="revolute">
    <origin rpy="0 0 0" xyz="0.080 0 0"/>
    <parent link="FANUC_lrmate200id_link_5"/>
    <child link="FANUC_lrmate200id_link_6"/>
    <axis xyz="-1 0 0"/>
    <limit effort="0" lower="-6.283185307179586" upper="6.283185307179586" velocity="17.453292519943297"/>
  </joint>


</robot>
